Workbook
Name Standortliste: 'Standorte'!$A$2:$A$101

Sheet Start
B2: Schnell erfassen: Verbrauchsmaterial
B5: 1. Datei unter eigenem Namen speichern. Jede neue Vorlage aus dem Programm oder dem Befehl stock-template hat 100 eigene feste Erfassungsnummern. Eine Kopie oder derselbe GitHub-Download behält dieselben Nummern.
B6: 2. Im Blatt Inventar eine Zeile je Artikel, Charge und Lagerort ausfüllen. Pflicht: Bezeichnung, Standort, Menge und Basiseinheit. Erfassungsnummern sind fest vorgegeben. Leere vorbereitete Zeilen werden beim Import ignoriert.
B7: 3. Menge immer als positive ganze Zahl in Basiseinheiten angeben, z. B. 20 Stück. Eine Packung mit 10 Stück bedeutet Menge 10 und Basiseinheit Stück. Ein Verpackungscode berechnet keine Menge. Nullbestände hier auslassen.
B8: 4. Charge und Verfall soweit bekannt ergänzen. Verfall als Text JJJJ-MM-TT, z. B. 2028-12-31. Nicht raten und keine Monatsdaten automatisch zum Monatsende erweitern. Unbekannte Charge oder unbekannter/abgelaufener Verfall wird in Quarantäne gebucht.
B9: 5. Fremdcode nimmt vorhandene Hersteller-/Verpackungscodes per USB-Handscanner auf, z. B. PZN oder GTIN. Alle Eingabefelder sind Text, damit führende Nullen bleiben. Der Code allein identifiziert noch keinen Artikel und keine Packungsgröße im Programm.
B10: 6. Die erzeugten Etiketten enthalten Erfassungsnummern für diese Liste, keine Hersteller- oder Chargenkennzeichnung. Optional am Erfassungsblatt oder Lagerbehälter verwenden; Originalkennzeichnungen nicht überkleben. Auf 100 % drucken und einen Barcode testen.
B11: 7. USB-Handscanner als Tastatur, Code 39 und Enter-Abschluss einstellen. Im Blatt Scanner Zelle B3 wählen, Erfassungsnummer oder Fremdcode scannen. Die Suche zeigt Grunddaten; mehrdeutige Codes werden gemeldet. Ein Scan erzeugt keine Buchung.
B12: 8. Standorte frei eintragen oder im Blatt Standorte sammeln. Beim Import ausdrücklich vorhandenen Programm-Lagerorten zuordnen. Für bestehende Artikel müssen Bezeichnung und Basiseinheit passen; bei mehrdeutigen Namen die Artikel-ID aus dem Katalog ergänzen.
B13: 9. Nur das Blatt Inventar als CSV UTF-8 speichern; die XLSX zusätzlich behalten. Im Programm Material-CSV öffnen und Importart wählen: Erstbestand für noch nicht erfasste Bestände; späterer Zugang nur für tatsächliche neue Lieferungen.
B14: 10. Vorschau prüfen: neue Artikel/Chargen, Menge, Standort und Quarantäne. Erstbestand wird abgelehnt, wenn der Artikelbestand am Ort schon erfasst wurde, auch mit Menge null. Für eine Bestandszählung die Bestandskorrektur im Programm verwenden, keine zusätzliche Eingangsbuchung.
B15: 11. Dieselbe Erfassungsnummer mit denselben Daten wird übersprungen, auch nach Entnahme oder Storno. Geänderte Daten zur gleichen Nummer werden abgelehnt. Für neue Lieferungen neue unbenutzte Erfassungsnummern verwenden; nicht alte Zeilen umschreiben.
B16: Grenzen: Überblick und dokumentierter Zugang, keine automatische Nutzbarkeitsfreigabe oder Packungsumrechnung. Die Tabelle bleibt nach dem Export offline; Bestandsänderungen im Programm werden nicht in Excel zurückgeschrieben. Keine Makros oder Barcode-Schriftarten.

Sheet Inventar
A1: Erfassungsnummer | B1: Bezeichnung | C1: Standort | D1: Menge | E1: Basiseinheit | F1: Charge | G1: Verfall | H1: Fremdcode | I1: Bemerkung | J1: Artikel-ID
A2: D-TEMPLATE0000-001
A3: D-TEMPLATE0000-002
A4: D-TEMPLATE0000-003
A5: D-TEMPLATE0000-004
A6: D-TEMPLATE0000-005
A7: D-TEMPLATE0000-006
A8: D-TEMPLATE0000-007
A9: D-TEMPLATE0000-008
A10: D-TEMPLATE0000-009
A11: D-TEMPLATE0000-010
A12: D-TEMPLATE0000-011
A13: D-TEMPLATE0000-012
... A101: D-TEMPLATE0000-100

Sheet Etiketten
A1: =Inventar!A2 -> D-TEMPLATE0000-001 | H1: =Inventar!A3 -> D-TEMPLATE0000-002
A3: =IF(Inventar!B2="","Noch nicht erfasst",Inventar!B2) -> Noch nicht erfasst | H3: =IF(Inventar!B3="","Noch nicht erfasst",Inventar!B3) -> Noch nicht erfasst
A5: =Inventar!A4 -> D-TEMPLATE0000-003 | H5: =Inventar!A5 -> D-TEMPLATE0000-004
A7: =IF(Inventar!B4="","Noch nicht erfasst",Inventar!B4) -> Noch nicht erfasst | H7: =IF(Inventar!B5="","Noch nicht erfasst",Inventar!B5) -> Noch nicht erfasst
A9: =Inventar!A6 -> D-TEMPLATE0000-005 | H9: =Inventar!A7 -> D-TEMPLATE0000-006
A11: =IF(Inventar!B6="","Noch nicht erfasst",Inventar!B6) -> Noch nicht erfasst | H11: =IF(Inventar!B7="","Noch nicht erfasst",Inventar!B7) -> Noch nicht erfasst
A13: =Inventar!A8 -> D-TEMPLATE0000-007 | H13: =Inventar!A9 -> D-TEMPLATE0000-008
A15: =IF(Inventar!B8="","Noch nicht erfasst",Inventar!B8) -> Noch nicht erfasst | H15: =IF(Inventar!B9="","Noch nicht erfasst",Inventar!B9) -> Noch nicht erfasst
A17: =Inventar!A10 -> D-TEMPLATE0000-009 | H17: =Inventar!A11 -> D-TEMPLATE0000-010
A19: =IF(Inventar!B10="","Noch nicht erfasst",Inventar!B10) -> Noch nicht erfasst | H19: =IF(Inventar!B11="","Noch nicht erfasst",Inventar!B11) -> Noch nicht erfasst
A21: =Inventar!A12 -> D-TEMPLATE0000-011 | H21: =Inventar!A13 -> D-TEMPLATE0000-012
A23: =IF(Inventar!B12="","Noch nicht erfasst",Inventar!B12) -> Noch nicht erfasst | H23: =IF(Inventar!B13="","Noch nicht erfasst",Inventar!B13) -> Noch nicht erfasst
A25: =Inventar!A14 -> D-TEMPLATE0000-013 | H25: =Inventar!A15 -> D-TEMPLATE0000-014
A27: =IF(Inventar!B14="","Noch nicht erfasst",Inventar!B14) -> Noch nicht erfasst | H27: =IF(Inventar!B15="","Noch nicht erfasst",Inventar!B15) -> Noch nicht erfasst
A29: =Inventar!A16 -> D-TEMPLATE0000-015 | H29: =Inventar!A17 -> D-TEMPLATE0000-016
A31: =IF(Inventar!B16="","Noch nicht erfasst",Inventar!B16) -> Noch nicht erfasst | H31: =IF(Inventar!B17="","Noch nicht erfasst",Inventar!B17) -> Noch nicht erfasst
A33: =Inventar!A18 -> D-TEMPLATE0000-017 | H33: =Inventar!A19 -> D-TEMPLATE0000-018
A35: =IF(Inventar!B18="","Noch nicht erfasst",Inventar!B18) -> Noch nicht erfasst | H35: =IF(Inventar!B19="","Noch nicht erfasst",Inventar!B19) -> Noch nicht erfasst
A37: =Inventar!A20 -> D-TEMPLATE0000-019 | H37: =Inventar!A21 -> D-TEMPLATE0000-020
A39: =IF(Inventar!B20="","Noch nicht erfasst",Inventar!B20) -> Noch nicht erfasst | H39: =IF(Inventar!B21="","Noch nicht erfasst",Inventar!B21) -> Noch nicht erfasst
A41: =Inventar!A22 -> D-TEMPLATE0000-021 | H41: =Inventar!A23 -> D-TEMPLATE0000-022
A43: =IF(Inventar!B22="","Noch nicht erfasst",Inventar!B22) -> Noch nicht erfasst | H43: =IF(Inventar!B23="","Noch nicht erfasst",Inventar!B23) -> Noch nicht erfasst
A45: =Inventar!A24 -> D-TEMPLATE0000-023 | H45: =Inventar!A25 -> D-TEMPLATE0000-024
A47: =IF(Inventar!B24="","Noch nicht erfasst",Inventar!B24) -> Noch nicht erfasst | H47: =IF(Inventar!B25="","Noch nicht erfasst",Inventar!B25) -> Noch nicht erfasst
A49: =Inventar!A26 -> D-TEMPLATE0000-025 | H49: =Inventar!A27 -> D-TEMPLATE0000-026
A51: =IF(Inventar!B26="","Noch nicht erfasst",Inventar!B26) -> Noch nicht erfasst | H51: =IF(Inventar!B27="","Noch nicht erfasst",Inventar!B27) -> Noch nicht erfasst
A53: =Inventar!A28 -> D-TEMPLATE0000-027 | H53: =Inventar!A29 -> D-TEMPLATE0000-028
A55: =IF(Inventar!B28="","Noch nicht erfasst",Inventar!B28) -> Noch nicht erfasst | H55: =IF(Inventar!B29="","Noch nicht erfasst",Inventar!B29) -> Noch nicht erfasst
A57: =Inventar!A30 -> D-TEMPLATE0000-029 | H57: =Inventar!A31 -> D-TEMPLATE0000-030
A59: =IF(Inventar!B30="","Noch nicht erfasst",Inventar!B30) -> Noch nicht erfasst | H59: =IF(Inventar!B31="","Noch nicht erfasst",Inventar!B31) -> Noch nicht erfasst
A61: =Inventar!A32 -> D-TEMPLATE0000-031 | H61: =Inventar!A33 -> D-TEMPLATE0000-032
A63: =IF(Inventar!B32="","Noch nicht erfasst",Inventar!B32) -> Noch nicht erfasst | H63: =IF(Inventar!B33="","Noch nicht erfasst",Inventar!B33) -> Noch nicht erfasst
A65: =Inventar!A34 -> D-TEMPLATE0000-033 | H65: =Inventar!A35 -> D-TEMPLATE0000-034
A67: =IF(Inventar!B34="","Noch nicht erfasst",Inventar!B34) -> Noch nicht erfasst | H67: =IF(Inventar!B35="","Noch nicht erfasst",Inventar!B35) -> Noch nicht erfasst
A69: =Inventar!A36 -> D-TEMPLATE0000-035 | H69: =Inventar!A37 -> D-TEMPLATE0000-036
A71: =IF(Inventar!B36="","Noch nicht erfasst",Inventar!B36) -> Noch nicht erfasst | H71: =IF(Inventar!B37="","Noch nicht erfasst",Inventar!B37) -> Noch nicht erfasst
A73: =Inventar!A38 -> D-TEMPLATE0000-037 | H73: =Inventar!A39 -> D-TEMPLATE0000-038
A75: =IF(Inventar!B38="","Noch nicht erfasst",Inventar!B38) -> Noch nicht erfasst | H75: =IF(Inventar!B39="","Noch nicht erfasst",Inventar!B39) -> Noch nicht erfasst
A77: =Inventar!A40 -> D-TEMPLATE0000-039 | H77: =Inventar!A41 -> D-TEMPLATE0000-040
A79: =IF(Inventar!B40="","Noch nicht erfasst",Inventar!B40) -> Noch nicht erfasst | H79: =IF(Inventar!B41="","Noch nicht erfasst",Inventar!B41) -> Noch nicht erfasst
...

Sheet Scanner
A1: Barcode suchen
C2: =SUBSTITUTE(SUBSTITUTE(SUBSTITUTE(B3,"~","~~"),"*","~*"),"?","~?")
A3: Hier scannen → | C3: =IFERROR(MATCH($C$2,Inventar!$A$2:$A$101,0),IFERROR(MATCH($C$2,Inventar!$H$2:$H$101,0),0)) -> 0
B4: B3 wählen, scannen, Enter; USB-Scanner sendet Tastatureingabe.
B5: =IF(B3="","",IF(COUNTIF(Inventar!$A$2:$A$101,$C$2)+COUNTIF(Inventar!$H$2:$H$101,$C$2)>1,"Mehrdeutiger Code – Inventar prüfen",IF(COUNTIF(Inventar!$A$2:$A$101,$C$2)+COUNTIF(Inventar!$H$2:$H$101,$C$2)=0,"Code nicht gefunden","Gefunden")))
A8: Erfassungsnummer | B8: =IF(OR($B$3="",$B$5<>"Gefunden"),"",IF(INDEX(Inventar!$A$2:$A$101,$C$3)="","",INDEX(Inventar!$A$2:$A$101,$C$3)))
A9: Bezeichnung | B9: =IF(OR($B$3="",$B$5<>"Gefunden"),"",IF(INDEX(Inventar!$B$2:$B$101,$C$3)="","",INDEX(Inventar!$B$2:$B$101,$C$3)))
A10: Standort | B10: =IF(OR($B$3="",$B$5<>"Gefunden"),"",IF(INDEX(Inventar!$C$2:$C$101,$C$3)="","",INDEX(Inventar!$C$2:$C$101,$C$3)))
A11: Menge | B11: =IF(OR($B$3="",$B$5<>"Gefunden"),"",IF(INDEX(Inventar!$D$2:$D$101,$C$3)="","",INDEX(Inventar!$D$2:$D$101,$C$3)))
A12: Basiseinheit | B12: =IF(OR($B$3="",$B$5<>"Gefunden"),"",IF(INDEX(Inventar!$E$2:$E$101,$C$3)="","",INDEX(Inventar!$E$2:$E$101,$C$3)))
A13: Charge | B13: =IF(OR($B$3="",$B$5<>"Gefunden"),"",IF(INDEX(Inventar!$F$2:$F$101,$C$3)="","",INDEX(Inventar!$F$2:$F$101,$C$3)))
A14: Verfall | B14: =IF(OR($B$3="",$B$5<>"Gefunden"),"",IF(INDEX(Inventar!$G$2:$G$101,$C$3)="","",INDEX(Inventar!$G$2:$G$101,$C$3)))
A15: Fremdcode | B15: =IF(OR($B$3="",$B$5<>"Gefunden"),"",IF(INDEX(Inventar!$H$2:$H$101,$C$3)="","",INDEX(Inventar!$H$2:$H$101,$C$3)))
A16: Bemerkung | B16: =IF(OR($B$3="",$B$5<>"Gefunden"),"",IF(INDEX(Inventar!$I$2:$I$101,$C$3)="","",INDEX(Inventar!$I$2:$I$101,$C$3)))
A17: Artikel-ID | B17: =IF(OR($B$3="",$B$5<>"Gefunden"),"",IF(INDEX(Inventar!$J$2:$J$101,$C$3)="","",INDEX(Inventar!$J$2:$J$101,$C$3)))

Sheet Standorte
A1: Standortnamen
B2: Hier eigene Standortnamen sammeln, z. B. Fahrzeug 1, Lager oder Tasche. Keine UUID nötig.
